/usr/local/lib/python2.7/dist-packages/sflock/decode/office.py:12: CryptographyDeprecationWarning: Python 2 is no longer supported by the Python core team. Support for it is now deprecated in cryptography, and will be removed in the next release.
  from cryptography.hazmat.backends import default_backend
2023-08-17 01:27:53,035 [cuckoo.core.startup] DEBUG: Imported modules...
2023-08-17 01:27:53,053 [elasticsearch] WARNING: [33mHEAD http://192.168.0.80:9200/_template/cuckoo_template [status:N/A request:0.000s][0m
Traceback (most recent call last):
  File "/usr/local/lib/python2.7/dist-packages/elasticsearch/connection/http_urllib3.py", line 114, in perform_request
    response = self.pool.urlopen(method, url, body, retries=False, headers=self.headers, **kw)
  File "/usr/local/lib/python2.7/dist-packages/urllib3/connectionpool.py", line 788, in urlopen
    method, url, error=e, _pool=self, _stacktrace=sys.exc_info()[2]
  File "/usr/local/lib/python2.7/dist-packages/urllib3/util/retry.py", line 525, in increment
    raise six.reraise(type(error), error, _stacktrace)
  File "/usr/local/lib/python2.7/dist-packages/urllib3/connectionpool.py", line 710, in urlopen
    chunked=chunked,
  File "/usr/local/lib/python2.7/dist-packages/urllib3/connectionpool.py", line 398, in _make_request
    conn.request(method, url, **httplib_request_kw)
  File "/usr/local/lib/python2.7/dist-packages/urllib3/connection.py", line 244, in request
    super(HTTPConnection, self).request(method, url, body=body, headers=headers)
  File "/usr/lib/python2.7/httplib.py", line 1103, in request
    self._send_request(method, url, body, headers)
  File "/usr/lib/python2.7/httplib.py", line 1143, in _send_request
    self.endheaders(body)
  File "/usr/lib/python2.7/httplib.py", line 1099, in endheaders
    self._send_output(message_body)
  File "/usr/lib/python2.7/httplib.py", line 913, in _send_output
    self.send(msg)
  File "/usr/lib/python2.7/httplib.py", line 875, in send
    self.connect()
  File "/usr/local/lib/python2.7/dist-packages/urllib3/connection.py", line 205, in connect
    conn = self._new_conn()
  File "/usr/local/lib/python2.7/dist-packages/urllib3/connection.py", line 187, in _new_conn
    self, "Failed to establish a new connection: %s" % e
NewConnectionError: <urllib3.connection.HTTPConnection object at 0x7f951e068190>: Failed to establish a new connection: [Errno 111] Connection refused
2023-08-17 01:27:53,054 [elasticsearch] WARNING: [33mHEAD http://192.168.0.80:9200/_template/cuckoo_template [status:N/A request:0.000s][0m
Traceback (most recent call last):
  File "/usr/local/lib/python2.7/dist-packages/elasticsearch/connection/http_urllib3.py", line 114, in perform_request
    response = self.pool.urlopen(method, url, body, retries=False, headers=self.headers, **kw)
  File "/usr/local/lib/python2.7/dist-packages/urllib3/connectionpool.py", line 788, in urlopen
    method, url, error=e, _pool=self, _stacktrace=sys.exc_info()[2]
  File "/usr/local/lib/python2.7/dist-packages/urllib3/util/retry.py", line 525, in increment
    raise six.reraise(type(error), error, _stacktrace)
  File "/usr/local/lib/python2.7/dist-packages/urllib3/connectionpool.py", line 710, in urlopen
    chunked=chunked,
  File "/usr/local/lib/python2.7/dist-packages/urllib3/connectionpool.py", line 398, in _make_request
    conn.request(method, url, **httplib_request_kw)
  File "/usr/local/lib/python2.7/dist-packages/urllib3/connection.py", line 244, in request
    super(HTTPConnection, self).request(method, url, body=body, headers=headers)
  File "/usr/lib/python2.7/httplib.py", line 1103, in request
    self._send_request(method, url, body, headers)
  File "/usr/lib/python2.7/httplib.py", line 1143, in _send_request
    self.endheaders(body)
  File "/usr/lib/python2.7/httplib.py", line 1099, in endheaders
    self._send_output(message_body)
  File "/usr/lib/python2.7/httplib.py", line 913, in _send_output
    self.send(msg)
  File "/usr/lib/python2.7/httplib.py", line 875, in send
    self.connect()
  File "/usr/local/lib/python2.7/dist-packages/urllib3/connection.py", line 205, in connect
    conn = self._new_conn()
  File "/usr/local/lib/python2.7/dist-packages/urllib3/connection.py", line 187, in _new_conn
    self, "Failed to establish a new connection: %s" % e
NewConnectionError: <urllib3.connection.HTTPConnection object at 0x7f951e068210>: Failed to establish a new connection: [Errno 111] Connection refused
2023-08-17 01:27:53,054 [elasticsearch] WARNING: [33mHEAD http://192.168.0.80:9200/_template/cuckoo_template [status:N/A request:0.000s][0m
Traceback (most recent call last):
  File "/usr/local/lib/python2.7/dist-packages/elasticsearch/connection/http_urllib3.py", line 114, in perform_request
    response = self.pool.urlopen(method, url, body, retries=False, headers=self.headers, **kw)
  File "/usr/local/lib/python2.7/dist-packages/urllib3/connectionpool.py", line 788, in urlopen
    method, url, error=e, _pool=self, _stacktrace=sys.exc_info()[2]
  File "/usr/local/lib/python2.7/dist-packages/urllib3/util/retry.py", line 525, in increment
    raise six.reraise(type(error), error, _stacktrace)
  File "/usr/local/lib/python2.7/dist-packages/urllib3/connectionpool.py", line 710, in urlopen
    chunked=chunked,
  File "/usr/local/lib/python2.7/dist-packages/urllib3/connectionpool.py", line 398, in _make_request
    conn.request(method, url, **httplib_request_kw)
  File "/usr/local/lib/python2.7/dist-packages/urllib3/connection.py", line 244, in request
    super(HTTPConnection, self).request(method, url, body=body, headers=headers)
  File "/usr/lib/python2.7/httplib.py", line 1103, in request
    self._send_request(method, url, body, headers)
  File "/usr/lib/python2.7/httplib.py", line 1143, in _send_request
    self.endheaders(body)
  File "/usr/lib/python2.7/httplib.py", line 1099, in endheaders
    self._send_output(message_body)
  File "/usr/lib/python2.7/httplib.py", line 913, in _send_output
    self.send(msg)
  File "/usr/lib/python2.7/httplib.py", line 875, in send
    self.connect()
  File "/usr/local/lib/python2.7/dist-packages/urllib3/connection.py", line 205, in connect
    conn = self._new_conn()
  File "/usr/local/lib/python2.7/dist-packages/urllib3/connection.py", line 187, in _new_conn
    self, "Failed to establish a new connection: %s" % e
NewConnectionError: <urllib3.connection.HTTPConnection object at 0x7f951e068110>: Failed to establish a new connection: [Errno 111] Connection refused
2023-08-17 01:27:53,055 [elasticsearch] WARNING: [33mHEAD http://192.168.0.80:9200/_template/cuckoo_template [status:N/A request:0.000s][0m
Traceback (most recent call last):
  File "/usr/local/lib/python2.7/dist-packages/elasticsearch/connection/http_urllib3.py", line 114, in perform_request
    response = self.pool.urlopen(method, url, body, retries=False, headers=self.headers, **kw)
  File "/usr/local/lib/python2.7/dist-packages/urllib3/connectionpool.py", line 788, in urlopen
    method, url, error=e, _pool=self, _stacktrace=sys.exc_info()[2]
  File "/usr/local/lib/python2.7/dist-packages/urllib3/util/retry.py", line 525, in increment
    raise six.reraise(type(error), error, _stacktrace)
  File "/usr/local/lib/python2.7/dist-packages/urllib3/connectionpool.py", line 710, in urlopen
    chunked=chunked,
  File "/usr/local/lib/python2.7/dist-packages/urllib3/connectionpool.py", line 398, in _make_request
    conn.request(method, url, **httplib_request_kw)
  File "/usr/local/lib/python2.7/dist-packages/urllib3/connection.py", line 244, in request
    super(HTTPConnection, self).request(method, url, body=body, headers=headers)
  File "/usr/lib/python2.7/httplib.py", line 1103, in request
    self._send_request(method, url, body, headers)
  File "/usr/lib/python2.7/httplib.py", line 1143, in _send_request
    self.endheaders(body)
  File "/usr/lib/python2.7/httplib.py", line 1099, in endheaders
    self._send_output(message_body)
  File "/usr/lib/python2.7/httplib.py", line 913, in _send_output
    self.send(msg)
  File "/usr/lib/python2.7/httplib.py", line 875, in send
    self.connect()
  File "/usr/local/lib/python2.7/dist-packages/urllib3/connection.py", line 205, in connect
    conn = self._new_conn()
  File "/usr/local/lib/python2.7/dist-packages/urllib3/connection.py", line 187, in _new_conn
    self, "Failed to establish a new connection: %s" % e
NewConnectionError: <urllib3.connection.HTTPConnection object at 0x7f951e068090>: Failed to establish a new connection: [Errno 111] Connection refused
Traceback (most recent call last):
  File "/usr/local/bin/cuckoo", line 8, in <module>
    sys.exit(main())
  File "/usr/local/lib/python2.7/dist-packages/click/core.py", line 716, in __call__
    return self.main(*args, **kwargs)
  File "/usr/local/lib/python2.7/dist-packages/click/core.py", line 696, in main
    rv = self.invoke(ctx)
  File "/usr/local/lib/python2.7/dist-packages/click/core.py", line 1060, in invoke
    return _process_result(sub_ctx.command.invoke(sub_ctx))
  File "/usr/local/lib/python2.7/dist-packages/click/core.py", line 889, in invoke
    return ctx.invoke(self.callback, **ctx.params)
  File "/usr/local/lib/python2.7/dist-packages/click/core.py", line 534, in invoke
    return callback(*args, **kwargs)
  File "/usr/local/lib/python2.7/dist-packages/click/decorators.py", line 17, in new_func
    return f(get_current_context(), *args, **kwargs)
  File "/usr/local/lib/python2.7/dist-packages/cuckoo/main.py", line 427, in process
    init_modules()
  File "/usr/local/lib/python2.7/dist-packages/cuckoo/core/startup.py", line 274, in init_modules
    module.init_once()
  File "/usr/local/lib/python2.7/dist-packages/cuckoo/reporting/elasticsearch.py", line 49, in init_once
    if not elastic.client.indices.exists_template(cls.template_name):
  File "/usr/local/lib/python2.7/dist-packages/elasticsearch/client/utils.py", line 73, in _wrapped
    return func(*args, params=params, **kwargs)
  File "/usr/local/lib/python2.7/dist-packages/elasticsearch/client/indices.py", line 475, in exists_template
    name), params=params)
  File "/usr/local/lib/python2.7/dist-packages/elasticsearch/transport.py", line 318, in perform_request
    status, headers, data = connection.perform_request(method, url, params, body, ignore=ignore, timeout=timeout)
  File "/usr/local/lib/python2.7/dist-packages/elasticsearch/connection/http_urllib3.py", line 123, in perform_request
    raise ConnectionError('N/A', str(e), e)
elasticsearch.exceptions.ConnectionError: ConnectionError(<urllib3.connection.HTTPConnection object at 0x7f951e068090>: Failed to establish a new connection: [Errno 111] Connection refused) caused by: NewConnectionError(<urllib3.connection.HTTPConnection object at 0x7f951e068090>: Failed to establish a new connection: [Errno 111] Connection refused)
