/usr/local/lib/python2.7/dist-packages/sflock/decode/office.py:12: CryptographyDeprecationWarning: Python 2 is no longer supported by the Python core team. Support for it is now deprecated in cryptography, and will be removed in the next release.
  from cryptography.hazmat.backends import default_backend
[31m
                      __
  .----..--.--..----.|  |--..-----..-----.
  |  __||  |  ||  __||    < |  _  ||  _  |
  |____||_____||____||__|__||_____||_____|[0m

 Cuckoo Sandbox [33m2.0.7[0m
 www.cuckoosandbox.org
 Copyright (c) 2010-2018

2023-08-17 01:27:42,844 [cuckoo] DEBUG: Increasing resource limit for number of open files to 1048576
2023-08-17 01:27:44,235 [cuckoo.core.startup] DEBUG: Imported modules...
2023-08-17 01:27:44,253 [elasticsearch] WARNING: [332023-08-17 01:27:44,394 [cuckoo.core.startup] DEBUG: Imported modules...
2023-08-17 01:27:44,411 [elasticsearch] WARNING: [33mHEAD http://192.168.0.80:9200/_template/cuckoo_template [status:N/A request:0.000s][0m
Traceback (most recent call last):
  File "/usr/local/lib/python2.7/dist-packages/elasticsearch/connection/http_urllib3.py", line 114, in perform_request
    response = self.pool.urlopen(method, url, body, retries=False, headers=self.headers, **kw)
  File "/usr/local/lib/python2.7/dist-packages/urllib3/connectionpool.py", line 788, in urlopen
    method, url, error=e, _pool=self, _stacktrace=sys.exc_info()[2]
  File "/usr/local/lib/python2.7/dist-packages/urllib3/util/retry.py", line 525, in increment
    raise six.reraise(type(error), error, _stacktrace)
  File "/usr/local/lib/python2.7/dist-packages/urllib3/connectionpool.py", line 710, in urlopen
    chunked=chunked,
  File "/usr/local/lib/python2.7/dist-packages/urllib3/connectionpool.py", line 398, in _make_request
    conn.request(method, url, **httplib_request_kw)
  File "/usr/local/lib/python2.7/dist-packages/urllib3/connection.py", line 244, in request
    super(HTTPConnection, self).request(method, url, body=body, headers=headers)
  File "/usr/lib/python2.7/httplib.py", line 1103, in request
    self._send_request(method, url, body, headers)
  File "/usr/lib/python2.7/httplib.py", line 1143, in _send_request
    self.endheaders(body)
  File "/usr/lib/python2.7/httplib.py", line 1099, in endheaders
    self._send_output(message_body)
  File "/usr/lib/python2.7/httplib.py", line 913, in _send_output
    self.send(msg)
  File "/usr/lib/python2.7/httplib.py", line 875, in send
    self.connect()
  File "/usr/local/lib/python2.7/dist-packages/urllib3/connection.py", line 205, in connect
    conn = self._new_conn()
  File "/usr/local/lib/python2.7/dist-packages/urllib3/connection.py", line 187, in _new_conn
    self, "Failed to establish a new connection: %s" % e
NewConnectionError: <urllib3.connection.HTTPConnection object at 0x7f2cb89ed050>: Failed to establish a new connection: [Errno 111] Connection refused
2023-08-17 01:27:44,412 [elasticsearch] WARNING: [33mHEAD http://192.168.0.80:9200/_template/cuckoo_template [status:N/A request:0.000s][0m
Traceback (most recent call last):
  File "/usr/local/lib/python2.7/dist-packages/elasticsearch/connection/http_urllib3.py", line 114, in perform_request
    response = self.pool.urlopen(method, url, body, retries=False, headers=self.headers, **kw)
  File "/usr/local/lib/python2.7/dist-packages/urllib3/connectionpool.py", line 788, in urlopen
    method, url, error=e, _pool=self, _stacktrace=sys.exc_info()[2]
  File "/usr/local/lib/python2.7/dist-packages/urllib3/util/retry.py", line 525, in increment
    raise six.reraise(type(error), error, _stacktrace)
  File "/usr/local/lib/python2.7/dist-packages/urllib3/connectionpool.py", line 710, in urlopen
    chunked=chunked,
  File "/usr/local/lib/python2.7/dist-packages/urllib3/connectionpool.py", line 398, in _make_request
    conn.request(method, url, **httplib_request_kw)
  File "/usr/local/lib/python2.7/dist-packages/urllib3/connection.py", line 244, in request
    super(HTTPConnection, self).request(method, url, body=body, headers=headers)
  File "/usr/lib/python2.7/httplib.py", line 1103, in request
    self._send_request(method, url, body, headers)
  File "/usr/lib/python2.7/httplib.py", line 1143, in _send_request
    self.endheaders(body)
  File "/usr/lib/python2.7/httplib.py", line 1099, in endheaders
    self._send_output(message_body)
  File "/usr/lib/python2.7/httplib.py", line 913, in _send_output
    self.send(msg)
  File "/usr/lib/python2.7/httplib.py", line 875, in send
    self.connect()
  File "/usr/local/lib/python2.7/dist-packages/urllib3/connection.py", line 205, in connect
    conn = self._new_conn()
  File "/usr/local/lib/python2.7/dist-packages/urllib3/connection.py", line 187, in _new_conn
    self, "Failed to establish a new connection: %s" % e
NewConnectionError: <urllib3.connection.HTTPConnection object at 0x7f2cb89ed0d0>: Failed to establish a new connection: [Errno 111] Connection refused
2023-08-17 01:27:44,413 [elasticsearch] WARNING: [33mHEAD http://192.168.0.80:9200/_template/cuckoo_template [status:N/A request:0.000s][0m
Traceback (most recent call last):
  File "/usr/local/lib/python2.7/dist-packages/elasticsearch/connection/http_urllib3.py", line 114, in perform_request
    response = self.pool.urlopen(method, url, body, retries=False, headers=self.headers, **kw)
  File "/usr/local/lib/python2.7/dist-packages/urllib3/connectionpool.py", line 788, in urlopen
    method, url, error=e, _pool=self, _stacktrace=sys.exc_info()[2]
  File "/usr/local/lib/python2.7/dist-packages/urllib3/util/retry.py", line 525, in increment
    raise six.reraise(type(error), error, _stacktrace)
  File "/usr/local/lib/python2.7/dist-packages/urllib3/connectionpool.py", line 710, in urlopen
    chunked=chunked,
  File "/usr/local/lib/python2.7/dist-packages/urllib3/connectionpool.py", line 398, in _make_request
    conn.request(method, url, **httplib_request_kw)
  File "/usr/local/lib/python2.7/dist-packages/urllib3/connection.py", line 244, in request
    super(HTTPConnection, self).request(method, url, body=body, headers=headers)
  File "/usr/lib/python2.7/httplib.py", line 1103, in request
    self._send_request(method, url, body, headers)
  File "/usr/lib/python2.7/httplib.py", line 1143, in _send_request
    self.endheaders(body)
  File "/usr/lib/python2.7/httplib.py", line 1099, in endheaders
    self._send_output(message_body)
  File "/usr/lib/python2.7/httplib.py", line 913, in _send_output
    self.send(msg)
  File "/usr/lib/python2.7/httplib.py", line 875, in send
    self.connect()
  File "/usr/local/lib/python2.7/dist-packages/urllib3/connection.py", line 205, in connect
    conn = self._new_conn()
  File "/usr/local/lib/python2.7/dist-packages/urllib3/connection.py", line 187, in _new_conn
    self, "Failed to establish a new connection: %s" % e
NewConnectionError: <urllib3.connection.HTTPConnection object at 0x7f2cb89ed090>: Failed to establish a new connection: [Errno 111] Connection refused
2023-08-17 01:27:44,413 [elasticsearch] WARNING: [33mHEAD http://192.168.0.80:9200/_template/cuckoo_template [status:N/A request:0.000s][0m
Traceback (most recent call last):
  File "/usr/local/lib/python2.7/dist-packages/elasticsearch/connection/http_urllib3.py", line 114, in perform_request
    response = self.pool.urlopen(method, url, body, retries=False, headers=self.headers, **kw)
  File "/usr/local/lib/python2.7/dist-packages/urllib3/connectionpool.py", line 788, in urlopen
    method, url, error=e, _pool=self, _stacktrace=sys.exc_info()[2]
  File "/usr/local/lib/python2.7/dist-packages/urllib3/util/retry.py", line 525, in increment
    raise six.reraise(type(error), error, _stacktrace)
  File "/usr/local/lib/python2.7/dist-packages/urllib3/connectionpool.py", line 710, in urlopen
    chunked=chunked,
  File "/usr/local/lib/python2.7/dist-packages/urllib3/connectionpool.py", line 398, in _make_request
    conn.request(method, url, **httplib_request_kw)
  File "/usr/local/lib/python2.7/dist-packages/urllib3/connection.py", line 244, in request
    super(HTTPConnection, self).request(method, url, body=body, headers=headers)
  File "/usr/lib/python2.7/httplib.py", line 1103, in request
    self._send_request(method, url, body, headers)
  File "/usr/lib/python2.7/httplib.py", line 1143, in _send_request
    self.endheaders(body)
  File "/usr/lib/python2.7/httplib.py", line 1099, in endheaders
    self._send_output(message_body)
  File "/usr/lib/python2.7/httplib.py", line 913, in _send_output
    self.send(msg)
  File "/usr/lib/python2.7/httplib.py", line 875, in send
    self.connect()
  File "/usr/local/lib/python2.7/dist-packages/urllib3/connection.py", line 205, in connect
    conn = self._new_conn()
  File "/usr/local/lib/python2.7/dist-packages/urllib3/connection.py", line 187, in _new_conn
    self, "Failed to establish a new connection: %s" % e
NewConnectionError: <urllib3.connection.HTTPConnection object at 0x7f2cb89ed050>: Failed to establish a new connection: [Errno 111] Connection refused
Oops! Cuckoo failed in an unhandled exception!
Sometimes bugs are already fixed in the development release, it is therefore recommended to retry with the latest development release available https://github.com/cuckoosandbox/cuckoo
If the error persists please open a new issue at https://github.com/cuckoosandbox/cuckoo/issues

=== Exception details ===
Cuckoo version: 2.0.7
OS version: posix
OS release: Ubuntu 16.04 xenial
Python version: 2.7.12
Python implementation: CPython
Machine arch: x86_64
Modules: adium-theme-ubuntu:0.3.4 alembic:1.0.10 androguard:3.0.1 argparse:1.2.1 attrs:21.4.0 beautifulsoup4:4.5.3 capstone:3.0.5rc2 cffi:1.15.1 chardet:2.3.0 click:6.6 colorama:0.3.7 configparser:4.0.2 contextlib2:0.6.0.post1 cryptography:3.3.2 cuckoo:2.0.7 distorm3:3.4.4 django-extensions:1.6.7 django:1.8.4 dpkt:1.8.7 ecdsa:0.18.0 egghatch:0.2.3 elasticsearch:5.3.0 enum34:1.1.10 flask-sqlalchemy:2.4.0 flask:0.12.2 functools32:3.2.3.post2 future:0.18.3 gevent:1.2.2 greenlet:2.0.2 httpreplay:0.2.6 idna:2.10 importlib-metadata:2.1.3 ipaddress:1.0.23 itsdangerous:1.1.0 jinja2:2.9.6 jsbeautifier:1.6.2 jsonschema:3.2.0 m2crypto:0.24.0 mako:1.1.6 markupsafe:1.1.1 meld3:2.0.1 olefile:0.43 oletools:0.51 pam:0.4.2 parsley:1.2 pathlib2:2.3.7.post1 peepdf:0.4.2 pefile2:1.2.11 pillow:3.2.0 pip:20.3.4 psutil:3.4.2 psycopg2:2.6.2 pyasn1-modules:0.0.7 pyasn1:0.1.9 pycparser:2.21 pycrypto:2.6.1 pyelftools:0.24 pyguacamole:0.6 pyliblzma:0.5.3 pymisp:2.4.106 pymongo:3.0.3 pyopenssl:21.0.0 pyrsistent:0.16.1 pyserial:3.0.1 python-dateutil:2.4.2 python-editor:1.0.4 python-magic:0.4.12 python:2.7.12 pythonaes:1.0 pyyaml:3.11 requests:2.13.0 roach:0.1.2 scandir:1.10.0 scapy:2.3.2 service-identity:16.0.0 setuptools:20.7.0 sflock:0.3.10 six:1.16.0 sqlalchemy:1.3.3 supervisor:3.3.4 suricata-update:1.2.2 suricata:6.0.3 tlslite-ng:0.6.0 torbrowser-launcher:0.2.4 twisted:16.0.0 txsocksx:0.0.0 typing:3.10.0.0 unicorn:1.0.1 unity-lens-photos:1.0 urllib3:1.26.15 vboxapi:1.0 virtualenv:15.0.1 volatility:2.6.1 wakeonlan:0.2.2 werkzeug:1.0.1 wheel:0.29.0 wsgiref:0.1.2 yara-python:3.6.3 zipp:1.2.0 zope.interface:4.1.3

2023-08-17 01:27:44,414 [cuckoo] ERROR: [31m[31mConnectionError: ConnectionError(<urllib3.connection.HTTPConnection object at 0x7f2cb89ed050>: Failed to establish a new connection: [Errno 111] Connection refused) caused by: NewConnectionError(<urllib3.connection.HTTPConnection object at 0x7f2cb89ed050>: Failed to establish a new connection: [Errno 111] Connection refused)[0m[0m
Traceback (most recent call last):
  File "/usr/local/lib/python2.7/dist-packages/cuckoo/main.py", line 297, in main
    cuckoo_init(level, ctx)
  File "/usr/local/lib/python2.7/dist-packages/cuckoo/main.py", line 190, in cuckoo_init
    init_modules()
  File "/usr/local/lib/python2.7/dist-packages/cuckoo/core/startup.py", line 274, in init_modules
    module.init_once()
  File "/usr/local/lib/python2.7/dist-packages/cuckoo/reporting/elasticsearch.py", line 49, in init_once
    if not elastic.client.indices.exists_template(cls.template_name):
  File "/usr/local/lib/python2.7/dist-packages/elasticsearch/client/utils.py", line 73, in _wrapped
    return func(*args, params=params, **kwargs)
  File "/usr/local/lib/python2.7/dist-packages/elasticsearch/client/indices.py", line 475, in exists_template
    name), params=params)
  File "/usr/local/lib/python2.7/dist-packages/elasticsearch/transport.py", line 318, in perform_request
    status, headers, data = connection.perform_request(method, url, params, body, ignore=ignore, timeout=timeout)
  File "/usr/local/lib/python2.7/dist-packages/elasticsearch/connection/http_urllib3.py", line 123, in perform_request
    raise ConnectionError('N/A', str(e), e)
ConnectionError: ConnectionError(<urllib3.connection.HTTPConnection object at 0x7f2cb89ed050>: Failed to establish a new connection: [Errno 111] Connection refused) caused by: NewConnectionError(<urllib3.connection.HTTPConnection object at 0x7f2cb89ed050>: Failed to establish a new connection: [Errno 111] Connection refused)
 Checking for updates...
[32m You're good to go![0m

 Our latest blogposts:
 * [33mCuckoo Sandbox 2.0.7[0m, June 19, 2019.
   [31mStability and security[0m
   More at https://cuckoosandbox.org/blog/207-interim-release

 * [33mIQY malspam campaign[0m, October 15, 2018.
   [31mAnalysis of a malspam campaign leveraging .IQY (Excel Web Query) files containing DDE to achieve code execution.[0m
   More at https://hatching.io/blog/iqy-malspam

 * [33mHooking VBScript execution in Cuckoo[0m, October 03, 2018.
   [31mDetails on implementation of Visual Basic Script instrumentation for Cuckoo Monitor for extraction of dynamically executed VBScript.[0m
   More at https://hatching.io/blog/vbscript-hooking

 * [33mCuckoo Sandbox 2.0.6 pentest[0m, September 18, 2018.
   [31mCuckoo Sandbox 2.0.6 public pentest performed by Cure53 and sponsored by PolySwarm![0m
   More at https://hatching.io/blog/cuckoo-206-pentest

 * [33mCuckoo Sandbox 2.0.6[0m, June 07, 2018.
   [31mInterim release awaiting the big release.[0m
   More at https://cuckoosandbox.org/blog/206-interim-release

